Workbook

Sheet README
A1: Capstone Literature Review Database — processed version
A2: Stress-response genes and hallmarks of aging in arthropods (41 papers)
A4: Sheets
A5: Cleaned_DB — one row per paper, cleaned text plus derived tags (taxon, research context, gene family, evidence type, direct aging measure).
A6: Flags — 0/1 indicator columns for every multi-valued field (stress types, hallmarks, gene families). Summary formulas read from here.
A7: Summary — counts by taxon, context, gene family, stress type, hallmark, method and evidence type (live formulas).
A8: Evidence_Map — stress type × aging hallmark matrix, showing where evidence clusters and where the gaps are.
A9: Data_QA — every correction made to the original sheet, and items that still need a manual decision.
A11: How tags were derived
A12: Hallmarks were mapped onto the López-Otín hallmarks of aging framework. "Oxidative stress" was merged with mitochondrial dysfunction; "reproductive decline" and "developmental arrest" with stem cell exhaustion.
A13: Evidence type: Causal = RNAi knockdown, silencing, recombinant protein injection or loss-of-function. Correlational = expression change or association only. Physiological/biomarker = no gene studied.
A14: Direct aging measure = the paper itself measures lifespan, longevity or age-dependent change in adults, rather than the link to aging being argued in the Inclusion Justification.
... A16: Litopenaeus vannamei and Penaeus vannamei are the same species (whiteleg / Pacific white shrimp) and were merged.

Sheet Summary
A1: Summary of the literature base
A2: All counts are live formulas on Cleaned_DB / Flags. Multi-valued fields (stress, hallmark, gene family) sum to more than the paper count.
A4: Total papers | B4: =COUNTA(Cleaned_DB!$A$2:$A$42) -> 41
A5: Distinct species | B5: =SUMPRODUCT(1/COUNTIF(Cleaned_DB!$C$2:$C$42,Cleaned_DB!$C$2:$C$42)) -> 22
A7: Taxon | B7: Papers | C7: % of papers
A8: Crustacea | B8: =COUNTIF(Cleaned_DB!$E$2:$E$42,"Crustacea") -> 22 | C8: =B8/$B$4 -> 0.53658537
A9: Insecta | B9: =COUNTIF(Cleaned_DB!$E$2:$E$42,"Insecta") -> 13 | C9: =B9/$B$4 -> 0.31707317
A10: Arachnida | B10: =COUNTIF(Cleaned_DB!$E$2:$E$42,"Arachnida") -> 5 | C10: =B10/$B$4 -> 0.12195122
A11: Multi-taxa (review) | B11: =COUNTIF(Cleaned_DB!$E$2:$E$42,"Multi-taxa (review)") -> 1 | C11: =B11/$B$4 -> 0.024390244
A13: Research context | B13: Papers | C13: % of papers
A14: Model / basic biology | B14: =COUNTIF(Cleaned_DB!$F$2:$F$42,"Model / basic biology") -> 19 | C14: =B14/$B$4 -> 0.46341463
A15: Aquaculture | B15: =COUNTIF(Cleaned_DB!$F$2:$F$42,"Aquaculture") -> 12 | C15: =B15/$B$4 -> 0.29268293
A16: Pest / parasite / vector | B16: =COUNTIF(Cleaned_DB!$F$2:$F$42,"Pest / parasite / vector") -> 7 | C16: =B16/$B$4 -> 0.17073171
A17: Ecotoxicology | B17: =COUNTIF(Cleaned_DB!$F$2:$F$42,"Ecotoxicology") -> 3 | C17: =B17/$B$4 -> 0.073170732
A19: Gene family (multi-valued) | B19: Papers | C19: % of papers
A20: HSP70 | B20: =SUM(Flags!$T$2:$T$42) -> 21 | C20: =B20/$B$4 -> 0.51219512
A21: HSP90 | B21: =SUM(Flags!$U$2:$U$42) -> 6 | C21: =B21/$B$4 -> 0.14634146
A22: Small HSPs | B22: =SUM(Flags!$V$2:$V$42) -> 5 | C22: =B22/$B$4 -> 0.12195122
A23: HSP40 (J-domain) | B23: =SUM(Flags!$W$2:$W$42) -> 3 | C23: =B23/$B$4 -> 0.073170732
A24: HSF1 | B24: =SUM(Flags!$X$2:$X$42) -> 3 | C24: =B24/$B$4 -> 0.073170732
A25: HSP60/10 | B25: =SUM(Flags!$Y$2:$Y$42) -> 1 | C25: =B25/$B$4 -> 0.024390244
A26: HSPs (unspecified) | B26: =SUM(Flags!$Z$2:$Z$42) -> 1 | C26: =B26/$B$4 -> 0.024390244
A27: Other chaperone (artemin) | B27: =SUM(Flags!$AA$2:$AA$42) -> 2 | C27: =B27/$B$4 -> 0.048780488
A28: Antioxidant enzymes | B28: =SUM(Flags!$AB$2:$AB$42) -> 5 | C28: =B28/$B$4 -> 0.12195122
A29: Mitochondrial (AOX) | B29: =SUM(Flags!$AC$2:$AC$42) -> 1 | C29: =B29/$B$4 -> 0.024390244
A30: Cuticle / structural | B30: =SUM(Flags!$AD$2:$AD$42) -> 2 | C30: =B30/$B$4 -> 0.048780488
A31: Other longevity genes | B31: =SUM(Flags!$AE$2:$AE$42) -> 1 | C31: =B31/$B$4 -> 0.024390244
A32: No gene (physiological biomarker) | B32: =SUM(Flags!$AF$2:$AF$42) -> 5 | C32: =B32/$B$4 -> 0.12195122
A34: Main function | B34: Papers | C34: % of papers
A35: Proteostasis / Chaperone | B35: =COUNTIF(Cleaned_DB!$J$2:$J$42,"Proteostasis / Chaperone") -> 20 | C35: =B35/$B$4 -> 0.48780488
A36: Antioxidant Defense | B36: =COUNTIF(Cleaned_DB!$J$2:$J$42,"Antioxidant Defense") -> 8 | C36: =B36/$B$4 -> 0.19512195
A37: Stress Response Regulation | B37: =COUNTIF(Cleaned_DB!$J$2:$J$42,"Stress Response Regulation") -> 7 | C37: =B37/$B$4 -> 0.17073171
A38: Other / Mixed | B38: =COUNTIF(Cleaned_DB!$J$2:$J$42,"Other / Mixed") -> 3 | C38: =B38/$B$4 -> 0.073170732
A39: Energy Metabolism | B39: =COUNTIF(Cleaned_DB!$J$2:$J$42,"Energy Metabolism") -> 2 | C39: =B39/$B$4 -> 0.048780488
A40: Cell Structure / Maintenance | B40: =COUNTIF(Cleaned_DB!$J$2:$J$42,"Cell Structure / Maintenance") -> 1 | C40: =B40/$B$4 -> 0.024390244
A42: Stress type (multi-valued) | B42: Papers | C42: % of papers
A43: Thermal | B43: =SUM(Flags!$B$2:$B$42) -> 9 | C43: =B43/$B$4 -> 0.2195122
A44: Oxidative | B44: =SUM(Flags!$C$2:$C$42) -> 2 | C44: =B44/$B$4 -> 0.048780488
A45: Chemical / Environmental | B45: =SUM(Flags!$D$2:$D$42) -> 6 | C45: =B45/$B$4 -> 0.14634146
A46: Pathogen / Immune | B46: =SUM(Flags!$E$2:$E$42) -> 9 | C46: =B46/$B$4 -> 0.2195122
...

Sheet Evidence_Map
A1: Evidence map — number of papers linking each stress type to each aging hallmark
A2: A paper tagged with 2 stress types and 2 hallmarks contributes to 4 cells. Blank-looking (0) cells are gaps in the literature base.
A4: Stress type ↓ / Hallmark → | B4: Loss of proteostasis | C4: Mitochondrial dysfunction / oxidative stress | D4: Altered intercellular communication | E4: Deregulated nutrient sensing | F4: Stem cell exhaustion / reproductive-developmental decline | G4: Genomic instability | H4: Epigenetic alterations | I4: Unmapped (non-standard label) | J4: Papers
A5: Thermal | B5: =SUMPRODUCT(Flags!$B$2:$B$42,Flags!$L$2:$L$42) -> 6 | C5: =SUMPRODUCT(Flags!$B$2:$B$42,Flags!$M$2:$M$42) -> 1 | D5: =SUMPRODUCT(Flags!$B$2:$B$42,Flags!$N$2:$N$42) -> 3 | E5: =SUMPRODUCT(Flags!$B$2:$B$42,Flags!$O$2:$O$42) -> 1 | F5: =SUMPRODUCT(Flags!$B$2:$B$42,Flags!$P$2:$P$42) -> 1 | G5: =SUMPRODUCT(Flags!$B$2:$B$42,Flags!$Q$2:$Q$42) -> 0 | H5: =SUMPRODUCT(Flags!$B$2:$B$42,Flags!$R$2:$R$42) -> 1 | I5: =SUMPRODUCT(Flags!$B$2:$B$42,Flags!$S$2:$S$42) -> 2 | J5: =SUM(Flags!$B$2:$B$42) -> 9
A6: Oxidative | B6: =SUMPRODUCT(Flags!$C$2:$C$42,Flags!$L$2:$L$42) -> 1 | C6: =SUMPRODUCT(Flags!$C$2:$C$42,Flags!$M$2:$M$42) -> 1 | D6: =SUMPRODUCT(Flags!$C$2:$C$42,Flags!$N$2:$N$42) -> 0 | E6: =SUMPRODUCT(Flags!$C$2:$C$42,Flags!$O$2:$O$42) -> 0 | F6: =SUMPRODUCT(Flags!$C$2:$C$42,Flags!$P$2:$P$42) -> 0 | G6: =SUMPRODUCT(Flags!$C$2:$C$42,Flags!$Q$2:$Q$42) -> 0 | H6: =SUMPRODUCT(Flags!$C$2:$C$42,Flags!$R$2:$R$42) -> 0 | I6: =SUMPRODUCT(Flags!$C$2:$C$42,Flags!$S$2:$S$42) -> 0 | J6: =SUM(Flags!$C$2:$C$42) -> 2
A7: Chemical / Environmental | B7: =SUMPRODUCT(Flags!$D$2:$D$42,Flags!$L$2:$L$42) -> 5 | C7: =SUMPRODUCT(Flags!$D$2:$D$42,Flags!$M$2:$M$42) -> 1 | D7: =SUMPRODUCT(Flags!$D$2:$D$42,Flags!$N$2:$N$42) -> 2 | E7: =SUMPRODUCT(Flags!$D$2:$D$42,Flags!$O$2:$O$42) -> 0 | F7: =SUMPRODUCT(Flags!$D$2:$D$42,Flags!$P$2:$P$42) -> 1 | G7: =SUMPRODUCT(Flags!$D$2:$D$42,Flags!$Q$2:$Q$42) -> 0 | H7: =SUMPRODUCT(Flags!$D$2:$D$42,Flags!$R$2:$R$42) -> 0 | I7: =SUMPRODUCT(Flags!$D$2:$D$42,Flags!$S$2:$S$42) -> 0 | J7: =SUM(Flags!$D$2:$D$42) -> 6
A8: Pathogen / Immune | B8: =SUMPRODUCT(Flags!$E$2:$E$42,Flags!$L$2:$L$42) -> 9 | C8: =SUMPRODUCT(Flags!$E$2:$E$42,Flags!$M$2:$M$42) -> 2 | D8: =SUMPRODUCT(Flags!$E$2:$E$42,Flags!$N$2:$N$42) -> 8 | E8: =SUMPRODUCT(Flags!$E$2:$E$42,Flags!$O$2:$O$42) -> 1 | F8: =SUMPRODUCT(Flags!$E$2:$E$42,Flags!$P$2:$P$42) -> 0 | G8: =SUMPRODUCT(Flags!$E$2:$E$42,Flags!$Q$2:$Q$42) -> 0 | H8: =SUMPRODUCT(Flags!$E$2:$E$42,Flags!$R$2:$R$42) -> 1 | I8: =SUMPRODUCT(Flags!$E$2:$E$42,Flags!$S$2:$S$42) -> 0 | J8: =SUM(Flags!$E$2:$E$42) -> 9
A9: Dietary / Nutritional | B9: =SUMPRODUCT(Flags!$F$2:$F$42,Flags!$L$2:$L$42) -> 4 | C9: =SUMPRODUCT(Flags!$F$2:$F$42,Flags!$M$2:$M$42) -> 1 | D9: =SUMPRODUCT(Flags!$F$2:$F$42,Flags!$N$2:$N$42) -> 1 | E9: =SUMPRODUCT(Flags!$F$2:$F$42,Flags!$O$2:$O$42) -> 1 | F9: =SUMPRODUCT(Flags!$F$2:$F$42,Flags!$P$2:$P$42) -> 0 | G9: =SUMPRODUCT(Flags!$F$2:$F$42,Flags!$Q$2:$Q$42) -> 0 | H9: =SUMPRODUCT(Flags!$F$2:$F$42,Flags!$R$2:$R$42) -> 0 | I9: =SUMPRODUCT(Flags!$F$2:$F$42,Flags!$S$2:$S$42) -> 0 | J9: =SUM(Flags!$F$2:$F$42) -> 4
A10: Developmental / Reproductive | B10: =SUMPRODUCT(Flags!$G$2:$G$42,Flags!$L$2:$L$42) -> 3 | C10: =SUMPRODUCT(Flags!$G$2:$G$42,Flags!$M$2:$M$42) -> 0 | D10: =SUMPRODUCT(Flags!$G$2:$G$42,Flags!$N$2:$N$42) -> 0 | E10: =SUMPRODUCT(Flags!$G$2:$G$42,Flags!$O$2:$O$42) -> 0 | F10: =SUMPRODUCT(Flags!$G$2:$G$42,Flags!$P$2:$P$42) -> 3 | G10: =SUMPRODUCT(Flags!$G$2:$G$42,Flags!$Q$2:$Q$42) -> 0 | H10: =SUMPRODUCT(Flags!$G$2:$G$42,Flags!$R$2:$R$42) -> 0 | I10: =SUMPRODUCT(Flags!$G$2:$G$42,Flags!$S$2:$S$42) -> 2 | J10: =SUM(Flags!$G$2:$G$42) -> 5
A11: Abiotic (general) | B11: =SUMPRODUCT(Flags!$H$2:$H$42,Flags!$L$2:$L$42) -> 4 | C11: =SUMPRODUCT(Flags!$H$2:$H$42,Flags!$M$2:$M$42) -> 2 | D11: =SUMPRODUCT(Flags!$H$2:$H$42,Flags!$N$2:$N$42) -> 1 | E11: =SUMPRODUCT(Flags!$H$2:$H$42,Flags!$O$2:$O$42) -> 0 | F11: =SUMPRODUCT(Flags!$H$2:$H$42,Flags!$P$2:$P$42) -> 1 | G11: =SUMPRODUCT(Flags!$H$2:$H$42,Flags!$Q$2:$Q$42) -> 0 | H11: =SUMPRODUCT(Flags!$H$2:$H$42,Flags!$R$2:$R$42) -> 0 | I11: =SUMPRODUCT(Flags!$H$2:$H$42,Flags!$S$2:$S$42) -> 0 | J11: =SUM(Flags!$H$2:$H$42) -> 6
A12: Genetic / Functional manipulation | B12: =SUMPRODUCT(Flags!$I$2:$I$42,Flags!$L$2:$L$42) -> 2 | C12: =SUMPRODUCT(Flags!$I$2:$I$42,Flags!$M$2:$M$42) -> 1 | D12: =SUMPRODUCT(Flags!$I$2:$I$42,Flags!$N$2:$N$42) -> 2 | E12: =SUMPRODUCT(Flags!$I$2:$I$42,Flags!$O$2:$O$42) -> 1 | F12: =SUMPRODUCT(Flags!$I$2:$I$42,Flags!$P$2:$P$42) -> 0 | G12: =SUMPRODUCT(Flags!$I$2:$I$42,Flags!$Q$2:$Q$42) -> 0 | H12: =SUMPRODUCT(Flags!$I$2:$I$42,Flags!$R$2:$R$42) -> 0 | I12: =SUMPRODUCT(Flags!$I$2:$I$42,Flags!$S$2:$S$42) -> 0 | J12: =SUM(Flags!$I$2:$I$42) -> 3
A13: Chronological aging | B13: =SUMPRODUCT(Flags!$J$2:$J$42,Flags!$L$2:$L$42) -> 2 | C13: =SUMPRODUCT(Flags!$J$2:$J$42,Flags!$M$2:$M$42) -> 3 | D13: =SUMPRODUCT(Flags!$J$2:$J$42,Flags!$N$2:$N$42) -> 0 | E13: =SUMPRODUCT(Flags!$J$2:$J$42,Flags!$O$2:$O$42) -> 0 | F13: =SUMPRODUCT(Flags!$J$2:$J$42,Flags!$P$2:$P$42) -> 0 | G13: =SUMPRODUCT(Flags!$J$2:$J$42,Flags!$Q$2:$Q$42) -> 1 | H13: =SUMPRODUCT(Flags!$J$2:$J$42,Flags!$R$2:$R$42) -> 1 | I13: =SUMPRODUCT(Flags!$J$2:$J$42,Flags!$S$2:$S$42) -> 1 | J13: =SUM(Flags!$J$2:$J$42) -> 6
A14: Radiation / hormesis | B14: =SUMPRODUCT(Flags!$K$2:$K$42,Flags!$L$2:$L$42) -> 1 | C14: =SUMPRODUCT(Flags!$K$2:$K$42,Flags!$M$2:$M$42) -> 0 | D14: =SUMPRODUCT(Flags!$K$2:$K$42,Flags!$N$2:$N$42) -> 0 | E14: =SUMPRODUCT(Flags!$K$2:$K$42,Flags!$O$2:$O$42) -> 0 | F14: =SUMPRODUCT(Flags!$K$2:$K$42,Flags!$P$2:$P$42) -> 0 | G14: =SUMPRODUCT(Flags!$K$2:$K$42,Flags!$Q$2:$Q$42) -> 1 | H14: =SUMPRODUCT(Flags!$K$2:$K$42,Flags!$R$2:$R$42) -> 0 | I14: =SUMPRODUCT(Flags!$K$2:$K$42,Flags!$S$2:$S$42) -> 0 | J14: =SUM(Flags!$K$2:$K$42) -> 1
A15: Papers | B15: =SUM(Flags!$L$2:$L$42) -> 29 | C15: =SUM(Flags!$M$2:$M$42) -> 11 | D15: =SUM(Flags!$N$2:$N$42) -> 12 | E15: =SUM(Flags!$O$2:$O$42) -> 3 | F15: =SUM(Flags!$P$2:$P$42) -> 5 | G15: =SUM(Flags!$Q$2:$Q$42) -> 2 | H15: =SUM(Flags!$R$2:$R$42) -> 2 | I15: =SUM(Flags!$S$2:$S$42) -> 3
A17: Gene family × evidence type
A18: Gene family | B18: Correlational (expression / association) | C18: Causal (loss/gain-of-function) | D18: Physiological / biomarker
A19: HSP70 | B19: =SUMPRODUCT(Flags!$T$2:$T$42,--(Cleaned_DB!$M$2:$M$42="Correlational (expression / association)")) -> 15 | C19: =SUMPRODUCT(Flags!$T$2:$T$42,--(Cleaned_DB!$M$2:$M$42="Causal (loss/gain-of-function)")) -> 6 | D19: =SUMPRODUCT(Flags!$T$2:$T$42,--(Cleaned_DB!$M$2:$M$42="Physiological / biomarker")) -> 0
A20: HSP90 | B20: =SUMPRODUCT(Flags!$U$2:$U$42,--(Cleaned_DB!$M$2:$M$42="Correlational (expression / association)")) -> 4 | C20: =SUMPRODUCT(Flags!$U$2:$U$42,--(Cleaned_DB!$M$2:$M$42="Causal (loss/gain-of-function)")) -> 2 | D20: =SUMPRODUCT(Flags!$U$2:$U$42,--(Cleaned_DB!$M$2:$M$42="Physiological / biomarker")) -> 0
A21: Small HSPs | B21: =SUMPRODUCT(Flags!$V$2:$V$42,--(Cleaned_DB!$M$2:$M$42="Correlational (expression / association)")) -> 3 | C21: =SUMPRODUCT(Flags!$V$2:$V$42,--(Cleaned_DB!$M$2:$M$42="Causal (loss/gain-of-function)")) -> 2 | D21: =SUMPRODUCT(Flags!$V$2:$V$42,--(Cleaned_DB!$M$2:$M$42="Physiological / biomarker")) -> 0
A22: HSP40 (J-domain) | B22: =SUMPRODUCT(Flags!$W$2:$W$42,--(Cleaned_DB!$M$2:$M$42="Correlational (expression / association)")) -> 2 | C22: =SUMPRODUCT(Flags!$W$2:$W$42,--(Cleaned_DB!$M$2:$M$42="Causal (loss/gain-of-function)")) -> 1 | D22: =SUMPRODUCT(Flags!$W$2:$W$42,--(Cleaned_DB!$M$2:$M$42="Physiological / biomarker")) -> 0
A23: HSF1 | B23: =SUMPRODUCT(Flags!$X$2:$X$42,--(Cleaned_DB!$M$2:$M$42="Correlational (expression / association)")) -> 1 | C23: =SUMPRODUCT(Flags!$X$2:$X$42,--(Cleaned_DB!$M$2:$M$42="Causal (loss/gain-of-function)")) -> 2 | D23: =SUMPRODUCT(Flags!$X$2:$X$42,--(Cleaned_DB!$M$2:$M$42="Physiological / biomarker")) -> 0
A24: HSP60/10 | B24: =SUMPRODUCT(Flags!$Y$2:$Y$42,--(Cleaned_DB!$M$2:$M$42="Correlational (expression / association)")) -> 1 | C24: =SUMPRODUCT(Flags!$Y$2:$Y$42,--(Cleaned_DB!$M$2:$M$42="Causal (loss/gain-of-function)")) -> 0 | D24: =SUMPRODUCT(Flags!$Y$2:$Y$42,--(Cleaned_DB!$M$2:$M$42="Physiological / biomarker")) -> 0
A25: HSPs (unspecified) | B25: =SUMPRODUCT(Flags!$Z$2:$Z$42,--(Cleaned_DB!$M$2:$M$42="Correlational (expression / association)")) -> 1 | C25: =SUMPRODUCT(Flags!$Z$2:$Z$42,--(Cleaned_DB!$M$2:$M$42="Causal (loss/gain-of-function)")) -> 0 | D25: =SUMPRODUCT(Flags!$Z$2:$Z$42,--(Cleaned_DB!$M$2:$M$42="Physiological / biomarker")) -> 0
A26: Other chaperone (artemin) | B26: =SUMPRODUCT(Flags!$AA$2:$AA$42,--(Cleaned_DB!$M$2:$M$42="Correlational (expression / association)")) -> 0 | C26: =SUMPRODUCT(Flags!$AA$2:$AA$42,--(Cleaned_DB!$M$2:$M$42="Causal (loss/gain-of-function)")) -> 2 | D26: =SUMPRODUCT(Flags!$AA$2:$AA$42,--(Cleaned_DB!$M$2:$M$42="Physiological / biomarker")) -> 0
A27: Antioxidant enzymes | B27: =SUMPRODUCT(Flags!$AB$2:$AB$42,--(Cleaned_DB!$M$2:$M$42="Correlational (expression / association)")) -> 5 | C27: =SUMPRODUCT(Flags!$AB$2:$AB$42,--(Cleaned_DB!$M$2:$M$42="Causal (loss/gain-of-function)")) -> 0 | D27: =SUMPRODUCT(Flags!$AB$2:$AB$42,--(Cleaned_DB!$M$2:$M$42="Physiological / biomarker")) -> 0
A28: Mitochondrial (AOX) | B28: =SUMPRODUCT(Flags!$AC$2:$AC$42,--(Cleaned_DB!$M$2:$M$42="Correlational (expression / association)")) -> 1 | C28: =SUMPRODUCT(Flags!$AC$2:$AC$42,--(Cleaned_DB!$M$2:$M$42="Causal (loss/gain-of-function)")) -> 0 | D28: =SUMPRODUCT(Flags!$AC$2:$AC$42,--(Cleaned_DB!$M$2:$M$42="Physiological / biomarker")) -> 0
A29: Cuticle / structural | B29: =SUMPRODUCT(Flags!$AD$2:$AD$42,--(Cleaned_DB!$M$2:$M$42="Correlational (expression / association)")) -> 1 | C29: =SUMPRODUCT(Flags!$AD$2:$AD$42,--(Cleaned_DB!$M$2:$M$42="Causal (loss/gain-of-function)")) -> 1 | D29: =SUMPRODUCT(Flags!$AD$2:$AD$42,--(Cleaned_DB!$M$2:$M$42="Physiological / biomarker")) -> 0
A30: Other longevity genes | B30: =SUMPRODUCT(Flags!$AE$2:$AE$42,--(Cleaned_DB!$M$2:$M$42="Correlational (expression / association)")) -> 1 | C30: =SUMPRODUCT(Flags!$AE$2:$AE$42,--(Cleaned_DB!$M$2:$M$42="Causal (loss/gain-of-function)")) -> 0 | D30: =SUMPRODUCT(Flags!$AE$2:$AE$42,--(Cleaned_DB!$M$2:$M$42="Physiological / biomarker")) -> 0
A31: No gene (physiological biomarker) | B31: =SUMPRODUCT(Flags!$AF$2:$AF$42,--(Cleaned_DB!$M$2:$M$42="Correlational (expression / association)")) -> 0 | C31: =SUMPRODUCT(Flags!$AF$2:$AF$42,--(Cleaned_DB!$M$2:$M$42="Causal (loss/gain-of-function)")) -> 0 | D31: =SUMPRODUCT(Flags!$AF$2:$AF$42,--(Cleaned_DB!$M$2:$M$42="Physiological / biomarker")) -> 5

Sheet Cleaned_DB
A1: ID | B1: Paper Title | C1: Species | D1: Common Name | E1: Taxon | F1: Research Context | G1: Stress Type(s) | H1: Gene(s) / Protein(s) | I1: Gene Family | J1: Main Function | K1: Aging Hallmark(s) | L1: Experimental Method | M1: Evidence Type | N1: Direct Aging Measure | O1: Key Findings | P1: Inclusion Justification
A2: 1 | B2: Effects of UV-B radiation on the survival, egg hatchability and transcript expression of antioxidant enzymes in a high-temperature adapted strain of Neoseiulus barkeri | C2: Neoseiulus barkeri | D2: Predatory mite | E2: Arachnida | F2: Pest / parasite / vector | G2: Oxidative | H2: SOD (3 genes), catalase | I2: Antioxidant enzymes | J2: Antioxidant Defense | K2: Mitochondrial dysfunction / oxidative stress | L2: Gene Expression Analysis | M2: Correlational (expression / association) | N2: No | O2: UV-B exposure decreases survival and egg hatchability. High-temperature-acclimated adults show weaker antioxidant (SOD/catalase) responses. SOD gene expression is upregulated in control but not in HTAS adults. | P2: Reduced antioxidant enzyme activity and altered SOD expression reflect impaired handling of reactive oxygen species, a key contributor to cellular aging.
A3: 2 | B3: Characterization and function analysis of Hsp60 and Hsp10 under different acute stresses in black tiger shrimp, Penaeus monodon | C3: Penaeus monodon | D3: Black tiger shrimp | E3: Crustacea | F3: Aquaculture | G3: Chemical / Environmental | H3: Hsp60, Hsp10 | I3: HSP60/10 | J3: Proteostasis / Chaperone | K3: Loss of proteostasis | L3: Gene Expression Analysis | M3: Correlational (expression / association) | N3: No | O3: Hsp60/Hsp10 complex shows ATPase and chaperone activity, slowing protein denaturation. Both genes support stress resilience via mitochondrial proteostasis. | P3: Enhanced chaperone activity maintains proper protein folding and mitochondrial protein quality, counteracting age-related proteostasis decline.
A4: 3 | B4: Identification and characterization of a laterally transferred alternative oxidase (AOX) in a terrestrial insect, the dipteran Pseudolycoriella hygida | C4: Pseudolycoriella hygida | D4: Fungus gnat | E4: Insecta | F4: Model / basic biology | G4: Genetic / Functional manipulation | H4: AOX | I4: Mitochondrial (AOX) | J4: Energy Metabolism | K4: Mitochondrial dysfunction / oxidative stress | L4: Protein / Enzyme Activity | M4: Correlational (expression / association) | N4: Yes | O4: AOX has three stage-specific isoforms and localizes to mitochondria. Cyanide-resistant respiration increases with age. Supports survival under respiratory inhibition. | P4: Changes in mitochondrial respiration and AOX function relate directly to age-associated mitochondrial stress and energy metabolism maintenance
A5: 4 | B5: Hsp70 Knockdown in the Brine Shrimp Artemia franciscana: Implication on Reproduction, Immune Response and Embryonic Cuticular Structure | C5: Artemia franciscana | D5: Brine shrimp | E5: Crustacea | F5: Model / basic biology | G5: Genetic / Functional manipulation | H5: Hsp70 | I5: HSP70 | J5: Proteostasis / Chaperone | K5: Loss of proteostasis; Deregulated nutrient sensing; Altered intercellular communication | L5: Gene Knockdown / RNAi | M5: Causal (loss/gain-of-function) | N5: No | O5: Hsp70 knockdown reduces gestational survival and offspring numbers. Causes exoskeleton damage, abnormal eye lens, defective cysts, shorter antennae. Downregulates cuticle/chitin and carbohydrate metabolism genes, decreases glycogen/trehalose. Lowers immune tolerance via Toll receptor downregulation. | P5: Hsp70 affects multiple cellular systems that normally decline with age, linking proteostasis, metabolism, and immunity to developmental and reproductive phenotypes.
A6: 5 | B6: Effects of Polystyrene Diet on the Growth and Development of Tenebrio molitor | C6: Tenebrio molitor | D6: Mealworm beetle | E6: Insecta | F6: Ecotoxicology | G6: Dietary / Nutritional | H6: HSP70 | I6: HSP70 | J6: Proteostasis / Chaperone | K6: Loss of proteostasis; Deregulated nutrient sensing | L6: Gene Expression Analysis | M6: Correlational (expression / association) | N6: No | O6: Polystyrene diet affects Tenebrio molitor development. Differential expression observed in Hsp70, chitinase, and cytochrome P450. Hsp70, an aging-related gene, responds to dietary stress, linking environmental stress to aging-related molecular pathways. | P6: Dietary stress triggers molecular pathways (proteostasis, metabolism) commonly altered during aging, highlighting how environmental factors intersect with aging mechanisms.
A7: 6 | B7: Effects of Dietary Mannan Oligosaccharides on Non-Specific Immunity, Intestinal Health, and Antibiotic Resistance Genes in Pacific White Shrimp Litopenaeus vannamei | C7: Penaeus vannamei | D7: Pacific white shrimp | E7: Crustacea | F7: Aquaculture | G7: Dietary / Nutritional | H7: HSP70 | I7: HSP70 | J7: Antioxidant Defense | K7: Loss of proteostasis; Altered intercellular communication | L7: Gene Expression Analysis | M7: Correlational (expression / association) | N7: No | O7: MOS supplementation in Litopenaeus vannamei upregulated immune genes, including Hsp70, Toll, and lysozyme. Hsp70 supports stress tolerance and cellular protection, linking diet to aging-related stress resistance. | P7: Dietary modulation influences proteostasis and immune pathways that typically decline with age, highlighting connections between nutrition, stress resilience, and aging mechanisms.
A8: 7 | B8: Transcriptional changes revealed water acidification leads to the immune response and ovary maturation delay in the Chinese mitten crab Eriocheir sinensis | C8: Eriocheir sinensis | D8: Chinese mitten crab | E8: Crustacea | F8: Aquaculture | G8: Chemical / Environmental | H8: HSP70, HSP90 | I8: HSP70; HSP90 | J8: Proteostasis / Chaperone | K8: Altered intercellular communication; Stem cell exhaustion / reproductive-developmental decline | L8: Gene Expression Analysis | M8: Correlational (expression / association) | N8: No | O8: Water acidification upregulated immune genes and downregulated ovarian maturation genes. Resulted in delayed ovary development. | P8: Environmental stress impacts both immune signaling and reproductive function, processes that are closely linked to age-related decline in physiology.
A9: 8 | B9: Transfer and effects of PET microfibers in Chironomus riparius | C9: Chironomus riparius | D9: Non-biting midge | E9: Insecta | F9: Ecotoxicology | G9: Chemical / Environmental | H9: HSP70 | I9: HSP70 | J9: Proteostasis / Chaperone | K9: Loss of proteostasis | L9: Histology / Microscopy | M9: Correlational (expression / association) | N9: No | O9: HSP70 levels unchanged between PET-exposed and control groups. Microfibers transferred from larvae to adults. No observable molecular or organismal toxicity. | P9: Inclusion demonstrates that this aging-related chaperone gene remained stable under environmental stress, serving as a baseline for proteostasis assessment.
A10: 9 | B10: Gene expression as age estimation marker in the larval stages of the forensic blowfly, Chrysomya albiceps, at different temperatures | C10: Chrysomya albiceps | D10: Blowfly | E10: Insecta | F10: Model / basic biology | G10: Abiotic (general) | H10: hsp90 | I10: HSP90 | J10: Proteostasis / Chaperone | K10: Loss of proteostasis | L10: Gene Expression Analysis | M10: Correlational (expression / association) | N10: No | O10: Hsp90 expression varies with temperature and age. Can potentially serve as an age-estimation marker. | P10: Hsp90 is a chaperone maintaining protein folding and stress response, processes that decline with age.
A11: 10 | B11: Cyst viability and stress tolerance upon heat shock protein 70 knockdown in the brine shrimp Artemia franciscana | C11: Artemia franciscana | D11: Brine shrimp | E11: Crustacea | F11: Model / basic biology | G11: Abiotic (general) | H11: Hsp70 | I11: HSP70 | J11: Proteostasis / Chaperone | K11: Loss of proteostasis | L11: Gene Knockdown / RNAi | M11: Causal (loss/gain-of-function) | N11: No | O11: Hsp70 knockdown did not impair cyst development. Reduced cyst stress tolerance; hatching percentage decreased under stress. | P11: Hsp70 supports cellular stress resistance, a key aging-related mechanism for maintaining protein homeostasis and organismal resilience.
A12: 11 | B12: The feeding of dietary Codonopsis pilosula polysaccharide enhances the immune responses, the expression of immune-related genes and the growth performance of red swamp crayfish (Procambarus clarkii) | C12: Procambarus clarkii | D12: Red swamp crayfish | E12: Crustacea | F12: Aquaculture | G12: Dietary / Nutritional | H12: mtMnsod, hsp70 | I12: HSP70; Antioxidant enzymes | J12: Antioxidant Defense | K12: Mitochondrial dysfunction / oxidative stress; Loss of proteostasis | L12: Gene Expression Analysis | M12: Correlational (expression / association) | N12: No | O12: Dietary CPP improved growth and antioxidant capacity. Upregulated mtMnsod and Hsp70. Optimal CPP level: 0.15–0.2%. | P12: Dietary supplementation modulates genes that maintain mitochondrial function and proteostasis, key processes in aging.
A13: 12 | B13: Cloning of four HSPA multigene family members in Haemaphysalis flava ticks | C13: Haemaphysalis flava | D13: Hard tick | E13: Arachnida | F13: Pest / parasite / vector | G13: Dietary / Nutritional | H13: HSPA2A, HSPA2B, HSPA5, HSPA9 | I13: HSP70 | J13: Proteostasis / Chaperone | K13: Loss of proteostasis | L13: Genomic / Sequence Analysis | M13: Correlational (expression / association) | N13: No | O13: Four HSPA (Hsp70) genes cloned. Expression varies by feeding stage; genes have distinct cellular localization and structures. | P13: Hsp70 family genes regulate protein folding and stress responses, central to maintaining proteostasis during aging.
... A42: 41 | B42: HSF-1 represses cuticle genes to maintain proteostasis during heat stress | C42: Tigriopus californicus | D42: Copepod | E42: Crustacea | F42: Model / basic biology | G42: Thermal | H42: HSF-1, Csp, Ctn, Cut | I42: HSF1; Cuticle / structural | J42: Cell Structure / Maintenance | K42: Loss of proteostasis | L42: Gene Knockdown / RNAi | M42: Causal (loss/gain-of-function) | N42: Yes | O42: Loss of HSF-1 increases cuticle gene expression, leading to more ubiquitinated proteins and accelerated aging. HSF-1 regulates non-canonical targets like chitin synthases. | P42: HSF-1 repression of cuticle/chitin genes maintains protein homeostasis; its loss accelerates protein misfolding and aging, demonstrating a direct gene-to-aging mechanism in arthropods.

Sheet Flags
A1: ID | B1: S: Thermal | C1: S: Oxidative | D1: S: Chemical / Environmental | E1: S: Pathogen / Immune | F1: S: Dietary / Nutritional | G1: S: Developmental / Reproductive | H1: S: Abiotic (general) | I1: S: Genetic / Functional manipulation | J1: S: Chronological aging | K1: S: Radiation / hormesis | L1: H: Loss of proteostasis | M1: H: Mitochondrial dysfunction / oxidative stress | N1: H: Altered intercellular communication | O1: H: Deregulated nutrient sensing | P1: H: Stem cell exhaustion / reproductive-developmental decline | Q1: H: Genomic instability | R1: H: Epigenetic alterations | S1: H: Unmapped (non-standard label) | T1: G: HSP70 | U1: G: HSP90 | V1: G: Small HSPs | W1: G: HSP40 (J-domain) | X1: G: HSF1 | Y1: G: HSP60/10 | Z1: G: HSPs (unspecified) | AA1: G: Other chaperone (artemin) | AB1: G: Antioxidant enzymes | AC1: G: Mitochondrial (AOX) | AD1: G: Cuticle / structural | AE1: G: Other longevity genes | AF1: G: No gene (physiological biomarker)
A2: 1 | B2: 0 | C2: 1 | D2: 0 | E2: 0 | F2: 0 | G2: 0 | H2: 0 | I2: 0 | J2: 0 | K2: 0 | L2: 0 | M2: 1 | N2: 0 | O2: 0 | P2: 0 | Q2: 0 | R2: 0 | S2: 0 | T2: 0 | U2: 0 | V2: 0 | W2: 0 | X2: 0 | Y2: 0 | Z2: 0 | AA2: 0 | AB2: 1 | AC2: 0 | AD2: 0 | AE2: 0 | AF2: 0
A3: 2 | B3: 0 | C3: 0 | D3: 1 | E3: 0 | F3: 0 | G3: 0 | H3: 0 | I3: 0 | J3: 0 | K3: 0 | L3: 1 | M3: 0 | N3: 0 | O3: 0 | P3: 0 | Q3: 0 | R3: 0 | S3: 0 | T3: 0 | U3: 0 | V3: 0 | W3: 0 | X3: 0 | Y3: 1 | Z3: 0 | AA3: 0 | AB3: 0 | AC3: 0 | AD3: 0 | AE3: 0 | AF3: 0
A4: 3 | B4: 0 | C4: 0 | D4: 0 | E4: 0 | F4: 0 | G4: 0 | H4: 0 | I4: 1 | J4: 0 | K4: 0 | L4: 0 | M4: 1 | N4: 0 | O4: 0 | P4: 0 | Q4: 0 | R4: 0 | S4: 0 | T4: 0 | U4: 0 | V4: 0 | W4: 0 | X4: 0 | Y4: 0 | Z4: 0 | AA4: 0 | AB4: 0 | AC4: 1 | AD4: 0 | AE4: 0 | AF4: 0
A5: 4 | B5: 0 | C5: 0 | D5: 0 | E5: 0 | F5: 0 | G5: 0 | H5: 0 | I5: 1 | J5: 0 | K5: 0 | L5: 1 | M5: 0 | N5: 1 | O5: 1 | P5: 0 | Q5: 0 | R5: 0 | S5: 0 | T5: 1 | U5: 0 | V5: 0 | W5: 0 | X5: 0 | Y5: 0 | Z5: 0 | AA5: 0 | AB5: 0 | AC5: 0 | AD5: 0 | AE5: 0 | AF5: 0
A6: 5 | B6: 0 | C6: 0 | D6: 0 | E6: 0 | F6: 1 | G6: 0 | H6: 0 | I6: 0 | J6: 0 | K6: 0 | L6: 1 | M6: 0 | N6: 0 | O6: 1 | P6: 0 | Q6: 0 | R6: 0 | S6: 0 | T6: 1 | U6: 0 | V6: 0 | W6: 0 | X6: 0 | Y6: 0 | Z6: 0 | AA6: 0 | AB6: 0 | AC6: 0 | AD6: 0 | AE6: 0 | AF6: 0
A7: 6 | B7: 0 | C7: 0 | D7: 0 | E7: 0 | F7: 1 | G7: 0 | H7: 0 | I7: 0 | J7: 0 | K7: 0 | L7: 1 | M7: 0 | N7: 1 | O7: 0 | P7: 0 | Q7: 0 | R7: 0 | S7: 0 | T7: 1 | U7: 0 | V7: 0 | W7: 0 | X7: 0 | Y7: 0 | Z7: 0 | AA7: 0 | AB7: 0 | AC7: 0 | AD7: 0 | AE7: 0 | AF7: 0
A8: 7 | B8: 0 | C8: 0 | D8: 1 | E8: 0 | F8: 0 | G8: 0 | H8: 0 | I8: 0 | J8: 0 | K8: 0 | L8: 0 | M8: 0 | N8: 1 | O8: 0 | P8: 1 | Q8: 0 | R8: 0 | S8: 0 | T8: 1 | U8: 1 | V8: 0 | W8: 0 | X8: 0 | Y8: 0 | Z8: 0 | AA8: 0 | AB8: 0 | AC8: 0 | AD8: 0 | AE8: 0 | AF8: 0
A9: 8 | B9: 0 | C9: 0 | D9: 1 | E9: 0 | F9: 0 | G9: 0 | H9: 0 | I9: 0 | J9: 0 | K9: 0 | L9: 1 | M9: 0 | N9: 0 | O9: 0 | P9: 0 | Q9: 0 | R9: 0 | S9: 0 | T9: 1 | U9: 0 | V9: 0 | W9: 0 | X9: 0 | Y9: 0 | Z9: 0 | AA9: 0 | AB9: 0 | AC9: 0 | AD9: 0 | AE9: 0 | AF9: 0
A10: 9 | B10: 0 | C10: 0 | D10: 0 | E10: 0 | F10: 0 | G10: 0 | H10: 1 | I10: 0 | J10: 0 | K10: 0 | L10: 1 | M10: 0 | N10: 0 | O10: 0 | P10: 0 | Q10: 0 | R10: 0 | S10: 0 | T10: 0 | U10: 1 | V10: 0 | W10: 0 | X10: 0 | Y10: 0 | Z10: 0 | AA10: 0 | AB10: 0 | AC10: 0 | AD10: 0 | AE10: 0 | AF10: 0
A11: 10 | B11: 0 | C11: 0 | D11: 0 | E11: 0 | F11: 0 | G11: 0 | H11: 1 | I11: 0 | J11: 0 | K11: 0 | L11: 1 | M11: 0 | N11: 0 | O11: 0 | P11: 0 | Q11: 0 | R11: 0 | S11: 0 | T11: 1 | U11: 0 | V11: 0 | W11: 0 | X11: 0 | Y11: 0 | Z11: 0 | AA11: 0 | AB11: 0 | AC11: 0 | AD11: 0 | AE11: 0 | AF11: 0
A12: 11 | B12: 0 | C12: 0 | D12: 0 | E12: 0 | F12: 1 | G12: 0 | H12: 0 | I12: 0 | J12: 0 | K12: 0 | L12: 1 | M12: 1 | N12: 0 | O12: 0 | P12: 0 | Q12: 0 | R12: 0 | S12: 0 | T12: 1 | U12: 0 | V12: 0 | W12: 0 | X12: 0 | Y12: 0 | Z12: 0 | AA12: 0 | AB12: 1 | AC12: 0 | AD12: 0 | AE12: 0 | AF12: 0
A13: 12 | B13: 0 | C13: 0 | D13: 0 | E13: 0 | F13: 1 | G13: 0 | H13: 0 | I13: 0 | J13: 0 | K13: 0 | L13: 1 | M13: 0 | N13: 0 | O13: 0 | P13: 0 | Q13: 0 | R13: 0 | S13: 0 | T13: 1 | U13: 0 | V13: 0 | W13: 0 | X13: 0 | Y13: 0 | Z13: 0 | AA13: 0 | AB13: 0 | AC13: 0 | AD13: 0 | AE13: 0 | AF13: 0
... A42: 41 | B42: 1 | C42: 0 | D42: 0 | E42: 0 | F42: 0 | G42: 0 | H42: 0 | I42: 0 | J42: 0 | K42: 0 | L42: 1 | M42: 0 | N42: 0 | O42: 0 | P42: 0 | Q42: 0 | R42: 0 | S42: 0 | T42: 0 | U42: 0 | V42: 0 | W42: 0 | X42: 1 | Y42: 0 | Z42: 0 | AA42: 0 | AB42: 0 | AC42: 0 | AD42: 1 | AE42: 0 | AF42: 0

Sheet Data_QA
A1: Paper ID | B1: Field | C1: Issue found | D1: Action taken
A2: 6 | B2: Species | C2: "Litopenaeus vannamei" is a synonym of Penaeus vannamei (same species counted twice) | D2: Harmonised to Penaeus vannamei
A3: 13 | B3: Stress Type | C3: Typo / stray character in "athogen / Immune Challenge." | D3: Mapped to canonical category
A4: 16 | B4: Species | C4: "Litopenaeus vannamei" is a synonym of Penaeus vannamei (same species counted twice) | D4: Harmonised to Penaeus vannamei
A5: 16 | B5: Gene(s) | C5: Malformed entry "HSP70 (LvHSP70" | D5: Changed to "HSP70 (LvHSP70)"
A6: 17 | B6: Gene(s) | C6: Malformed entry "HSP70, HSP90," | D6: Changed to "HSP70, HSP90"
A7: 23 | B7: Aging Hallmark | C7: Non-standard label "Aging-related / developmental regulation of diapause survival" | D7: Flagged as Unmapped; needs manual assignment to a hallmark
A8: 24 | B8: Aging Hallmark | C8: Non-standard label "Aging / developmental stage-dependent gene expression" | D8: Flagged as Unmapped; needs manual assignment to a hallmark
A9: 25 | B9: Species | C9: "Litopenaeus vannamei" is a synonym of Penaeus vannamei (same species counted twice) | D9: Harmonised to Penaeus vannamei
A10: 28 | B10: Stress Type | C10: Typo / stray character in ": Abiotic Stress (General)." | D10: Mapped to canonical category
A11: 29 | B11: Aging Hallmark | C11: Non-standard label "Aging / Stress response & Developmental regulation" | D11: Flagged as Unmapped; needs manual assignment to a hallmark
A12: 30 | B12: Species | C12: "Litopenaeus vannamei" is a synonym of Penaeus vannamei (same species counted twice) | D12: Harmonised to Penaeus vannamei
A13: 32 | B13: Stress Type | C13: Typo / stray character in "ging / Chronological Aging." | D13: Mapped to canonical category
... A16: 38 | B16: Key Findings | C16: Typo "ipid" | D16: Changed to "Lipid"
A17: All | B17: Stress Type / Hallmark | C17: Multiple values packed into one cell with inconsistent line breaks and trailing periods | D17: Split into canonical categories; 0/1 flags in Flags sheet
A18: All | B18: Common Name / Group | C18: 27 spelling variants for 23 species (e.g. "House fly" vs "Housefly", "Brine shrimp / Crustacean") | D18: Rebuilt from species name; taxon moved to its own column
A19: All | B19: Metadata | C19: No year, authors, journal or DOI columns | D19: Not fixable from this sheet — recommend adding before the review is written up
A20: All | B20: Experimental Method | C20: 9 of 41 papers coded "Other / Mixed" | D20: Left as is; consider recoding (e.g. lifespan assay, biomarker assay)
A21: 8 | B21: Key Findings | C21: Null result (no HSP70 change, no toxicity) | D21: Kept — negative results are informative; tagged as correlational
